Workbook

Sheet Relevé hebdo
A1: Relevé hebdomadaire — chiffres bruts (comptes nationaux exclus)
A2: Semaine (lundi) | B2: Complexe | C2: Note Google | D2: Avis Google | E2: Abonnés Instagram | F2: Posts Instagram | G2: Abonnés Facebook | H2: Abonnés TikTok | I2: Vidéos TikTok | J2: Total abonnés | K2: Remarques
A3: 2026-06-22 | B3: Le client | C3: 4.6 | D3: 767 | E3: 1606 | F3: 304 | G3: 3434 | H3: 553 | I3: 18 | J3: =IF(SUM(E3,G3,H3)=0,"",SUM(E3,G3,H3))
A4: 2026-06-22 | B4: Concurrent A | C4: 4.9 | D4: 1927 | E4: 2705 | F4: 265 | J4: =IF(SUM(E4,G4,H4)=0,"",SUM(E4,G4,H4)) | K4: FB non récupéré ; pas de TikTok
A5: 2026-06-22 | B5: Concurrent B | C5: 4.9 | D5: 478 | E5: 2392 | F5: 293 | G5: 1012 | H5: 583 | I5: 130 | J5: =IF(SUM(E5,G5,H5)=0,"",SUM(E5,G5,H5)) | K5: TikTok actif (vidéo 223k vues)
A6: 2026-06-22 | B6: Concurrent C | C6: 4.6 | D6: 886 | G6: 2066 | J6: =IF(SUM(E6,G6,H6)=0,"",SUM(E6,G6,H6)) | K6: Insta non récupéré ; pas de TikTok
A7: 2026-06-22 | B7: Concurrent D | C7: 4.4 | D7: 569 | E7: 1494 | F7: 505 | G7: 1738 | J7: =IF(SUM(E7,G7,H7)=0,"",SUM(E7,G7,H7)) | K7: → KoJump ; pas de TikTok
A8: 2026-06-22 | B8: Concurrent E | C8: 4.1 | D8: 501 | E8: 2479 | F8: 502 | G8: 1600 | J8: =IF(SUM(E8,G8,H8)=0,"",SUM(E8,G8,H8)) | K8: Pas de TikTok
A9: 2026-06-22 | B9: Concurrent F | C9: 4.1 | D9: 1355 | F9: 675 | G9: 977 | J9: =IF(SUM(E9,G9,H9)=0,"",SUM(E9,G9,H9)) | K9: Insta national EXCLU ; FB local
A10: 2026-06-22 | B10: Concurrent G | C10: 4.9 | D10: 224 | F10: 126 | J10: =IF(SUM(E10,G10,H10)=0,"",SUM(E10,G10,H10)) | K10: Comptes Insta+FB nationaux EXCLUS
A11: 2026-06-29 | B11: Le client | C11: 4.6 | D11: 767 | E11: 1604 | F11: 304 | G11: 3434 | H11: 553 | I11: 18 | J11: =IF(SUM(E11,G11,H11)=0,"",SUM(E11,G11,H11)) | K11: TikTok dormant : dernier post 04/04/2026 ; pic vues 7335 (juil. 2025)
A12: 2026-06-29 | B12: Concurrent A | C12: 4.9 | D12: 1929 | E12: 2707 | F12: 265 | J12: =IF(SUM(E12,G12,H12)=0,"",SUM(E12,G12,H12)) | K12: FB non scrapable ; pas de TikTok
A13: 2026-06-29 | B13: Concurrent B | C13: 4.9 | D13: 480 | E13: 2409 | F13: 292 | G13: 1013 | H13: 591 | I13: 131 | J13: =IF(SUM(E13,G13,H13)=0,"",SUM(E13,G13,H13)) | K13: TikTok très actif (5 vidéos en juin) ; pic vues récent 1134
A14: 2026-06-29 | B14: Concurrent C | C14: 4.6 | D14: 886 | J14: =IF(SUM(E14,G14,H14)=0,"",SUM(E14,G14,H14)) | K14: Insta non récupéré ; FB non récupéré (not_available) ; pas de TikTok
A15: 2026-06-29 | B15: Concurrent D | C15: 4.4 | D15: 569 | E15: 1493 | F15: 505 | G15: 1738 | J15: =IF(SUM(E15,G15,H15)=0,"",SUM(E15,G15,H15)) | K15: Pas de TikTok
A16: 2026-06-29 | B16: Concurrent E | C16: 4.1 | D16: 501 | E16: 2485 | F16: 504 | G16: 1600 | J16: =IF(SUM(E16,G16,H16)=0,"",SUM(E16,G16,H16)) | K16: Pas de TikTok
A17: 2026-06-29 | B17: Concurrent F | C17: 4.1 | D17: 1357 | G17: 977 | J17: =IF(SUM(E17,G17,H17)=0,"",SUM(E17,G17,H17)) | K17: Insta national EXCLU ; FB local
A18: 2026-06-29 | B18: Concurrent G | C18: 4.8 | D18: 241 | J18: =IF(SUM(E18,G18,H18)=0,"",SUM(E18,G18,H18)) | K18: Comptes Insta+FB nationaux EXCLUS
A19: 2026-07-06 | B19: Le client | C19: 4.6 | D19: 767 | E19: 1603 | F19: 304 | G19: 3434 | H19: 552 | I19: 18 | J19: =IF(SUM(E19,G19,H19)=0,"",SUM(E19,G19,H19)) | K19: TikTok dormant : dernier post 04/04/2026 (2472 vues) ; pic récent 7340 (juil. 2025)
A20: 2026-07-06 | B20: Concurrent A | C20: 4.9 | D20: 1950 | E20: 2708 | F20: 267 | J20: =IF(SUM(E20,G20,H20)=0,"",SUM(E20,G20,H20)) | K20: FB non scrapable ; pas de TikTok
A21: 2026-07-06 | B21: Concurrent B | C21: 4.9 | D21: 480 | E21: 2410 | F21: 296 | G21: 1016 | H21: 595 | I21: 135 | J21: =IF(SUM(E21,G21,H21)=0,"",SUM(E21,G21,H21)) | K21: TikTok en forte activité : 2 vidéos le 04/07 (44,2k et 38,3k vues) — pic exceptionnel
A22: 2026-07-06 | B22: Concurrent C | C22: 4.6 | D22: 886 | J22: =IF(SUM(E22,G22,H22)=0,"",SUM(E22,G22,H22)) | K22: Insta non tenté ; FB not_available ; pas de TikTok
A23: 2026-07-06 | B23: Concurrent D | C23: 4.4 | D23: 569 | E23: 1496 | F23: 505 | G23: 1739 | J23: =IF(SUM(E23,G23,H23)=0,"",SUM(E23,G23,H23)) | K23: Pas de TikTok
A24: 2026-07-06 | B24: Concurrent E | C24: 4.1 | D24: 502 | E24: 2488 | F24: 505 | G24: 1600 | J24: =IF(SUM(E24,G24,H24)=0,"",SUM(E24,G24,H24)) | K24: Pas de TikTok
A25: 2026-07-06 | B25: Concurrent F | C25: 4.1 | D25: 1357 | G25: 976 | J25: =IF(SUM(E25,G25,H25)=0,"",SUM(E25,G25,H25)) | K25: Insta national EXCLU ; FB local
A26: 2026-07-06 | B26: Concurrent G | C26: 4.8 | D26: 253 | J26: =IF(SUM(E26,G26,H26)=0,"",SUM(E26,G26,H26)) | K26: Comptes Insta+FB nationaux EXCLUS
A27: 2026-07-13 | B27: Le client | C27: 4.6 | D27: 766 | E27: 1604 | F27: 304 | G27: 3435 | H27: 552 | I27: 18 | J27: =IF(SUM(E27,G27,H27)=0,"",SUM(E27,G27,H27)) | K27: TikTok stable ; pic vues récent 7340 inchangé vs semaine dernière
A28: 2026-07-13 | B28: Concurrent A | C28: 4.9 | D28: 1971 | E28: 2714 | F28: 270 | J28: =IF(SUM(E28,G28,H28)=0,"",SUM(E28,G28,H28)) | K28: FB non scrapable ; pas de TikTok ; +21 avis Google vs semaine dernière
A29: 2026-07-13 | B29: Concurrent B | C29: 4.9 | D29: 481 | E29: 2416 | F29: 300 | G29: 1016 | H29: 613 | I29: 138 | J29: =IF(SUM(E29,G29,H29)=0,"",SUM(E29,G29,H29)) | K29: Buzz TikTok : vue max 152 400 relevée (nouveau pic, à confirmer date vidéo)
A30: 2026-07-13 | B30: Concurrent C | C30: 4.6 | D30: 888 | J30: =IF(SUM(E30,G30,H30)=0,"",SUM(E30,G30,H30)) | K30: Insta non tenté ; FB non récupéré (not_available) ; pas de TikTok
A31: 2026-07-13 | B31: Concurrent D | C31: 4.4 | D31: 570 | E31: 1498 | F31: 506 | G31: 1739 | J31: =IF(SUM(E31,G31,H31)=0,"",SUM(E31,G31,H31)) | K31: Pas de TikTok
A32: 2026-07-13 | B32: Concurrent E | C32: 4.1 | D32: 505 | E32: 2500 | F32: 508 | G32: 1711 | J32: =IF(SUM(E32,G32,H32)=0,"",SUM(E32,G32,H32)) | K32: Pas de TikTok ; FB +111 abonnés vs semaine dernière
A33: 2026-07-13 | B33: Concurrent F | C33: 4.1 | D33: 1361 | G33: 977 | J33: =IF(SUM(E33,G33,H33)=0,"",SUM(E33,G33,H33)) | K33: Insta national EXCLU ; FB local
A34: 2026-07-13 | B34: Concurrent G | C34: 4.8 | D34: 273 | J34: =IF(SUM(E34,G34,H34)=0,"",SUM(E34,G34,H34)) | K34: Comptes Insta+FB nationaux EXCLUS ; +20 avis Google vs semaine dernière
A35: 2026-07-20 | B35: Le client | C35: 4.6 | D35: 768 | E35: 1606 | F35: 305 | G35: 3438 | H35: 551 | I35: 18 | J35: =IF(SUM(E35,G35,H35)=0,"",SUM(E35,G35,H35)) | K35: TikTok dormant : dernier post 04/04/2026 (2482 vues) ; pic vues récent 7342 inchangé
A36: 2026-07-20 | B36: Concurrent A | C36: 4.9 | D36: 1988 | E36: 2719 | F36: 273 | J36: =IF(SUM(E36,G36,H36)=0,"",SUM(E36,G36,H36)) | K36: FB non scrapable ; pas de TikTok ; +17 avis Google vs S-07-13
A37: 2026-07-20 | B37: Concurrent B | C37: 4.9 | D37: 481 | E37: 2418 | F37: 303 | G37: 1021 | H37: 635 | I37: 143 | J37: =IF(SUM(E37,G37,H37)=0,"",SUM(E37,G37,H37)) | K37: Buzz TikTok : vue max 311 000 (vidéo 10/07/2026), nouveau pic ; TikTok +22 abonnés ; FB +5
A38: 2026-07-20 | B38: Concurrent C | C38: 4.6 | D38: 889 | J38: =IF(SUM(E38,G38,H38)=0,"",SUM(E38,G38,H38)) | K38: Insta non tenté ; FB non récupéré (not_available) ; pas de TikTok
A39: 2026-07-20 | B39: Concurrent D | C39: 4.4 | D39: 571 | E39: 1497 | F39: 506 | G39: 1738 | J39: =IF(SUM(E39,G39,H39)=0,"",SUM(E39,G39,H39)) | K39: Pas de TikTok ; IG -1 / FB -1 vs S-07-13
A40: 2026-07-20 | B40: Concurrent E | C40: 4.1 | D40: 507 | E40: 2510 | F40: 508 | G40: 1723 | J40: =IF(SUM(E40,G40,H40)=0,"",SUM(E40,G40,H40)) | K40: Pas de TikTok ; IG +10 / FB +12 vs S-07-13
...

Sheet Dashboard KPI (tendance)
A1: Tendance % depuis le début du reporting
A2: Évolution en % entre la 1ʳᵉ et la dernière semaine. Vert=hausse, Rouge=baisse. Visible dès la 2ᵉ semaine.
A3: Complexe | B3: Δ% Avis Google | C3: Δ% Abonnés Insta | D3: Δ% Abonnés FB | E3: Δ% Abonnés TikTok | F3: Δ% Total abonnés
A4: Le client | B4: =IFERROR(IF(OR(INDEX('Relevé hebdo'!$D$3:$D$2000,MATCH($A4,'Relevé hebdo'!$B$3:$B$2000,0))="",INDEX('Relevé hebdo'!$D$3:$D$2000,MATCH($A4,'Relevé hebdo'!$B$3:$B$2000,0))=0),"",LOOKUP(2,1/(('Relevé hebdo'!$B$3:$B$2000=$A4)*('Relevé hebdo'!$D$3:$D$2000<>"")),'Relevé hebdo'!$D$3:$D$2000)/INDEX('Relevé hebdo'!$D$3:$D$2000,MATCH($A4,'Relevé hebdo'!$B$3:$B$2000,0))-1),"") | C4: =IFERROR(IF(OR(INDEX('Relevé hebdo'!$E$3:$E$2000,MATCH($A4,'Relevé hebdo'!$B$3:$B$2000,0))="",INDEX('Relevé hebdo'!$E$3:$E$2000,MATCH($A4,'Relevé hebdo'!$B$3:$B$2000,0))=0),"",LOOKUP(2,1/(('Relevé hebdo'!$B$3:$B$2000=$A4)*('Relevé hebdo'!$E$3:$E$2000<>"")),'Relevé hebdo'!$E$3:$E$2000)/INDEX('Relevé hebdo'!$E$3:$E$2000,MATCH($A4,'Relevé hebdo'!$B$3:$B$2000,0))-1),"") | D4: =IFERROR(IF(OR(INDEX('Relevé hebdo'!$G$3:$G$2000,MATCH($A4,'Relevé hebdo'!$B$3:$B$2000,0))="",INDEX('Relevé hebdo'!$G$3:$G$2000,MATCH($A4,'Relevé hebdo'!$B$3:$B$2000,0))=0),"",LOOKUP(2,1/(('Relevé hebdo'!$B$3:$B$2000=$A4)*('Relevé hebdo'!$G$3:$G$2000<>"")),'Relevé hebdo'!$G$3:$G$2000)/INDEX('Relevé hebdo'!$G$3:$G$2000,MATCH($A4,'Relevé hebdo'!$B$3:$B$2000,0))-1),"") | E4: =IFERROR(IF(OR(INDEX('Relevé hebdo'!$H$3:$H$2000,MATCH($A4,'Relevé hebdo'!$B$3:$B$2000,0))="",INDEX('Relevé hebdo'!$H$3:$H$2000,MATCH($A4,'Relevé hebdo'!$B$3:$B$2000,0))=0),"",LOOKUP(2,1/(('Relevé hebdo'!$B$3:$B$2000=$A4)*('Relevé hebdo'!$H$3:$H$2000<>"")),'Relevé hebdo'!$H$3:$H$2000)/INDEX('Relevé hebdo'!$H$3:$H$2000,MATCH($A4,'Relevé hebdo'!$B$3:$B$2000,0))-1),"") | F4: =IFERROR(IF(OR(INDEX('Relevé hebdo'!$J$3:$J$2000,MATCH($A4,'Relevé hebdo'!$B$3:$B$2000,0))="",INDEX('Relevé hebdo'!$J$3:$J$2000,MATCH($A4,'Relevé hebdo'!$B$3:$B$2000,0))=0),"",LOOKUP(2,1/(('Relevé hebdo'!$B$3:$B$2000=$A4)*('Relevé hebdo'!$J$3:$J$2000<>"")),'Relevé hebdo'!$J$3:$J$2000)/INDEX('Relevé hebdo'!$J$3:$J$2000,MATCH($A4,'Relevé hebdo'!$B$3:$B$2000,0))-1),"")
A5: Concurrent A | B5: =IFERROR(IF(OR(INDEX('Relevé hebdo'!$D$3:$D$2000,MATCH($A5,'Relevé hebdo'!$B$3:$B$2000,0))="",INDEX('Relevé hebdo'!$D$3:$D$2000,MATCH($A5,'Relevé hebdo'!$B$3:$B$2000,0))=0),"",LOOKUP(2,1/(('Relevé hebdo'!$B$3:$B$2000=$A5)*('Relevé hebdo'!$D$3:$D$2000<>"")),'Relevé hebdo'!$D$3:$D$2000)/INDEX('Relevé hebdo'!$D$3:$D$2000,MATCH($A5,'Relevé hebdo'!$B$3:$B$2000,0))-1),"") | C5: =IFERROR(IF(OR(INDEX('Relevé hebdo'!$E$3:$E$2000,MATCH($A5,'Relevé hebdo'!$B$3:$B$2000,0))="",INDEX('Relevé hebdo'!$E$3:$E$2000,MATCH($A5,'Relevé hebdo'!$B$3:$B$2000,0))=0),"",LOOKUP(2,1/(('Relevé hebdo'!$B$3:$B$2000=$A5)*('Relevé hebdo'!$E$3:$E$2000<>"")),'Relevé hebdo'!$E$3:$E$2000)/INDEX('Relevé hebdo'!$E$3:$E$2000,MATCH($A5,'Relevé hebdo'!$B$3:$B$2000,0))-1),"") | D5: =IFERROR(IF(OR(INDEX('Relevé hebdo'!$G$3:$G$2000,MATCH($A5,'Relevé hebdo'!$B$3:$B$2000,0))="",INDEX('Relevé hebdo'!$G$3:$G$2000,MATCH($A5,'Relevé hebdo'!$B$3:$B$2000,0))=0),"",LOOKUP(2,1/(('Relevé hebdo'!$B$3:$B$2000=$A5)*('Relevé hebdo'!$G$3:$G$2000<>"")),'Relevé hebdo'!$G$3:$G$2000)/INDEX('Relevé hebdo'!$G$3:$G$2000,MATCH($A5,'Relevé hebdo'!$B$3:$B$2000,0))-1),"") | E5: =IFERROR(IF(OR(INDEX('Relevé hebdo'!$H$3:$H$2000,MATCH($A5,'Relevé hebdo'!$B$3:$B$2000,0))="",INDEX('Relevé hebdo'!$H$3:$H$2000,MATCH($A5,'Relevé hebdo'!$B$3:$B$2000,0))=0),"",LOOKUP(2,1/(('Relevé hebdo'!$B$3:$B$2000=$A5)*('Relevé hebdo'!$H$3:$H$2000<>"")),'Relevé hebdo'!$H$3:$H$2000)/INDEX('Relevé hebdo'!$H$3:$H$2000,MATCH($A5,'Relevé hebdo'!$B$3:$B$2000,0))-1),"") | F5: =IFERROR(IF(OR(INDEX('Relevé hebdo'!$J$3:$J$2000,MATCH($A5,'Relevé hebdo'!$B$3:$B$2000,0))="",INDEX('Relevé hebdo'!$J$3:$J$2000,MATCH($A5,'Relevé hebdo'!$B$3:$B$2000,0))=0),"",LOOKUP(2,1/(('Relevé hebdo'!$B$3:$B$2000=$A5)*('Relevé hebdo'!$J$3:$J$2000<>"")),'Relevé hebdo'!$J$3:$J$2000)/INDEX('Relevé hebdo'!$J$3:$J$2000,MATCH($A5,'Relevé hebdo'!$B$3:$B$2000,0))-1),"")
A6: Concurrent B | B6: =IFERROR(IF(OR(INDEX('Relevé hebdo'!$D$3:$D$2000,MATCH($A6,'Relevé hebdo'!$B$3:$B$2000,0))="",INDEX('Relevé hebdo'!$D$3:$D$2000,MATCH($A6,'Relevé hebdo'!$B$3:$B$2000,0))=0),"",LOOKUP(2,1/(('Relevé hebdo'!$B$3:$B$2000=$A6)*('Relevé hebdo'!$D$3:$D$2000<>"")),'Relevé hebdo'!$D$3:$D$2000)/INDEX('Relevé hebdo'!$D$3:$D$2000,MATCH($A6,'Relevé hebdo'!$B$3:$B$2000,0))-1),"") | C6: =IFERROR(IF(OR(INDEX('Relevé hebdo'!$E$3:$E$2000,MATCH($A6,'Relevé hebdo'!$B$3:$B$2000,0))="",INDEX('Relevé hebdo'!$E$3:$E$2000,MATCH($A6,'Relevé hebdo'!$B$3:$B$2000,0))=0),"",LOOKUP(2,1/(('Relevé hebdo'!$B$3:$B$2000=$A6)*('Relevé hebdo'!$E$3:$E$2000<>"")),'Relevé hebdo'!$E$3:$E$2000)/INDEX('Relevé hebdo'!$E$3:$E$2000,MATCH($A6,'Relevé hebdo'!$B$3:$B$2000,0))-1),"") | D6: =IFERROR(IF(OR(INDEX('Relevé hebdo'!$G$3:$G$2000,MATCH($A6,'Relevé hebdo'!$B$3:$B$2000,0))="",INDEX('Relevé hebdo'!$G$3:$G$2000,MATCH($A6,'Relevé hebdo'!$B$3:$B$2000,0))=0),"",LOOKUP(2,1/(('Relevé hebdo'!$B$3:$B$2000=$A6)*('Relevé hebdo'!$G$3:$G$2000<>"")),'Relevé hebdo'!$G$3:$G$2000)/INDEX('Relevé hebdo'!$G$3:$G$2000,MATCH($A6,'Relevé hebdo'!$B$3:$B$2000,0))-1),"") | E6: =IFERROR(IF(OR(INDEX('Relevé hebdo'!$H$3:$H$2000,MATCH($A6,'Relevé hebdo'!$B$3:$B$2000,0))="",INDEX('Relevé hebdo'!$H$3:$H$2000,MATCH($A6,'Relevé hebdo'!$B$3:$B$2000,0))=0),"",LOOKUP(2,1/(('Relevé hebdo'!$B$3:$B$2000=$A6)*('Relevé hebdo'!$H$3:$H$2000<>"")),'Relevé hebdo'!$H$3:$H$2000)/INDEX('Relevé hebdo'!$H$3:$H$2000,MATCH($A6,'Relevé hebdo'!$B$3:$B$2000,0))-1),"") | F6: =IFERROR(IF(OR(INDEX('Relevé hebdo'!$J$3:$J$2000,MATCH($A6,'Relevé hebdo'!$B$3:$B$2000,0))="",INDEX('Relevé hebdo'!$J$3:$J$2000,MATCH($A6,'Relevé hebdo'!$B$3:$B$2000,0))=0),"",LOOKUP(2,1/(('Relevé hebdo'!$B$3:$B$2000=$A6)*('Relevé hebdo'!$J$3:$J$2000<>"")),'Relevé hebdo'!$J$3:$J$2000)/INDEX('Relevé hebdo'!$J$3:$J$2000,MATCH($A6,'Relevé hebdo'!$B$3:$B$2000,0))-1),"")
A7: Concurrent C | B7: =IFERROR(IF(OR(INDEX('Relevé hebdo'!$D$3:$D$2000,MATCH($A7,'Relevé hebdo'!$B$3:$B$2000,0))="",INDEX('Relevé hebdo'!$D$3:$D$2000,MATCH($A7,'Relevé hebdo'!$B$3:$B$2000,0))=0),"",LOOKUP(2,1/(('Relevé hebdo'!$B$3:$B$2000=$A7)*('Relevé hebdo'!$D$3:$D$2000<>"")),'Relevé hebdo'!$D$3:$D$2000)/INDEX('Relevé hebdo'!$D$3:$D$2000,MATCH($A7,'Relevé hebdo'!$B$3:$B$2000,0))-1),"") | C7: =IFERROR(IF(OR(INDEX('Relevé hebdo'!$E$3:$E$2000,MATCH($A7,'Relevé hebdo'!$B$3:$B$2000,0))="",INDEX('Relevé hebdo'!$E$3:$E$2000,MATCH($A7,'Relevé hebdo'!$B$3:$B$2000,0))=0),"",LOOKUP(2,1/(('Relevé hebdo'!$B$3:$B$2000=$A7)*('Relevé hebdo'!$E$3:$E$2000<>"")),'Relevé hebdo'!$E$3:$E$2000)/INDEX('Relevé hebdo'!$E$3:$E$2000,MATCH($A7,'Relevé hebdo'!$B$3:$B$2000,0))-1),"") | D7: =IFERROR(IF(OR(INDEX('Relevé hebdo'!$G$3:$G$2000,MATCH($A7,'Relevé hebdo'!$B$3:$B$2000,0))="",INDEX('Relevé hebdo'!$G$3:$G$2000,MATCH($A7,'Relevé hebdo'!$B$3:$B$2000,0))=0),"",LOOKUP(2,1/(('Relevé hebdo'!$B$3:$B$2000=$A7)*('Relevé hebdo'!$G$3:$G$2000<>"")),'Relevé hebdo'!$G$3:$G$2000)/INDEX('Relevé hebdo'!$G$3:$G$2000,MATCH($A7,'Relevé hebdo'!$B$3:$B$2000,0))-1),"") | E7: =IFERROR(IF(OR(INDEX('Relevé hebdo'!$H$3:$H$2000,MATCH($A7,'Relevé hebdo'!$B$3:$B$2000,0))="",INDEX('Relevé hebdo'!$H$3:$H$2000,MATCH($A7,'Relevé hebdo'!$B$3:$B$2000,0))=0),"",LOOKUP(2,1/(('Relevé hebdo'!$B$3:$B$2000=$A7)*('Relevé hebdo'!$H$3:$H$2000<>"")),'Relevé hebdo'!$H$3:$H$2000)/INDEX('Relevé hebdo'!$H$3:$H$2000,MATCH($A7,'Relevé hebdo'!$B$3:$B$2000,0))-1),"") | F7: =IFERROR(IF(OR(INDEX('Relevé hebdo'!$J$3:$J$2000,MATCH($A7,'Relevé hebdo'!$B$3:$B$2000,0))="",INDEX('Relevé hebdo'!$J$3:$J$2000,MATCH($A7,'Relevé hebdo'!$B$3:$B$2000,0))=0),"",LOOKUP(2,1/(('Relevé hebdo'!$B$3:$B$2000=$A7)*('Relevé hebdo'!$J$3:$J$2000<>"")),'Relevé hebdo'!$J$3:$J$2000)/INDEX('Relevé hebdo'!$J$3:$J$2000,MATCH($A7,'Relevé hebdo'!$B$3:$B$2000,0))-1),"")
A8: Concurrent D | B8: =IFERROR(IF(OR(INDEX('Relevé hebdo'!$D$3:$D$2000,MATCH($A8,'Relevé hebdo'!$B$3:$B$2000,0))="",INDEX('Relevé hebdo'!$D$3:$D$2000,MATCH($A8,'Relevé hebdo'!$B$3:$B$2000,0))=0),"",LOOKUP(2,1/(('Relevé hebdo'!$B$3:$B$2000=$A8)*('Relevé hebdo'!$D$3:$D$2000<>"")),'Relevé hebdo'!$D$3:$D$2000)/INDEX('Relevé hebdo'!$D$3:$D$2000,MATCH($A8,'Relevé hebdo'!$B$3:$B$2000,0))-1),"") | C8: =IFERROR(IF(OR(INDEX('Relevé hebdo'!$E$3:$E$2000,MATCH($A8,'Relevé hebdo'!$B$3:$B$2000,0))="",INDEX('Relevé hebdo'!$E$3:$E$2000,MATCH($A8,'Relevé hebdo'!$B$3:$B$2000,0))=0),"",LOOKUP(2,1/(('Relevé hebdo'!$B$3:$B$2000=$A8)*('Relevé hebdo'!$E$3:$E$2000<>"")),'Relevé hebdo'!$E$3:$E$2000)/INDEX('Relevé hebdo'!$E$3:$E$2000,MATCH($A8,'Relevé hebdo'!$B$3:$B$2000,0))-1),"") | D8: =IFERROR(IF(OR(INDEX('Relevé hebdo'!$G$3:$G$2000,MATCH($A8,'Relevé hebdo'!$B$3:$B$2000,0))="",INDEX('Relevé hebdo'!$G$3:$G$2000,MATCH($A8,'Relevé hebdo'!$B$3:$B$2000,0))=0),"",LOOKUP(2,1/(('Relevé hebdo'!$B$3:$B$2000=$A8)*('Relevé hebdo'!$G$3:$G$2000<>"")),'Relevé hebdo'!$G$3:$G$2000)/INDEX('Relevé hebdo'!$G$3:$G$2000,MATCH($A8,'Relevé hebdo'!$B$3:$B$2000,0))-1),"") | E8: =IFERROR(IF(OR(INDEX('Relevé hebdo'!$H$3:$H$2000,MATCH($A8,'Relevé hebdo'!$B$3:$B$2000,0))="",INDEX('Relevé hebdo'!$H$3:$H$2000,MATCH($A8,'Relevé hebdo'!$B$3:$B$2000,0))=0),"",LOOKUP(2,1/(('Relevé hebdo'!$B$3:$B$2000=$A8)*('Relevé hebdo'!$H$3:$H$2000<>"")),'Relevé hebdo'!$H$3:$H$2000)/INDEX('Relevé hebdo'!$H$3:$H$2000,MATCH($A8,'Relevé hebdo'!$B$3:$B$2000,0))-1),"") | F8: =IFERROR(IF(OR(INDEX('Relevé hebdo'!$J$3:$J$2000,MATCH($A8,'Relevé hebdo'!$B$3:$B$2000,0))="",INDEX('Relevé hebdo'!$J$3:$J$2000,MATCH($A8,'Relevé hebdo'!$B$3:$B$2000,0))=0),"",LOOKUP(2,1/(('Relevé hebdo'!$B$3:$B$2000=$A8)*('Relevé hebdo'!$J$3:$J$2000<>"")),'Relevé hebdo'!$J$3:$J$2000)/INDEX('Relevé hebdo'!$J$3:$J$2000,MATCH($A8,'Relevé hebdo'!$B$3:$B$2000,0))-1),"")
A9: Concurrent E | B9: =IFERROR(IF(OR(INDEX('Relevé hebdo'!$D$3:$D$2000,MATCH($A9,'Relevé hebdo'!$B$3:$B$2000,0))="",INDEX('Relevé hebdo'!$D$3:$D$2000,MATCH($A9,'Relevé hebdo'!$B$3:$B$2000,0))=0),"",LOOKUP(2,1/(('Relevé hebdo'!$B$3:$B$2000=$A9)*('Relevé hebdo'!$D$3:$D$2000<>"")),'Relevé hebdo'!$D$3:$D$2000)/INDEX('Relevé hebdo'!$D$3:$D$2000,MATCH($A9,'Relevé hebdo'!$B$3:$B$2000,0))-1),"") | C9: =IFERROR(IF(OR(INDEX('Relevé hebdo'!$E$3:$E$2000,MATCH($A9,'Relevé hebdo'!$B$3:$B$2000,0))="",INDEX('Relevé hebdo'!$E$3:$E$2000,MATCH($A9,'Relevé hebdo'!$B$3:$B$2000,0))=0),"",LOOKUP(2,1/(('Relevé hebdo'!$B$3:$B$2000=$A9)*('Relevé hebdo'!$E$3:$E$2000<>"")),'Relevé hebdo'!$E$3:$E$2000)/INDEX('Relevé hebdo'!$E$3:$E$2000,MATCH($A9,'Relevé hebdo'!$B$3:$B$2000,0))-1),"") | D9: =IFERROR(IF(OR(INDEX('Relevé hebdo'!$G$3:$G$2000,MATCH($A9,'Relevé hebdo'!$B$3:$B$2000,0))="",INDEX('Relevé hebdo'!$G$3:$G$2000,MATCH($A9,'Relevé hebdo'!$B$3:$B$2000,0))=0),"",LOOKUP(2,1/(('Relevé hebdo'!$B$3:$B$2000=$A9)*('Relevé hebdo'!$G$3:$G$2000<>"")),'Relevé hebdo'!$G$3:$G$2000)/INDEX('Relevé hebdo'!$G$3:$G$2000,MATCH($A9,'Relevé hebdo'!$B$3:$B$2000,0))-1),"") | E9: =IFERROR(IF(OR(INDEX('Relevé hebdo'!$H$3:$H$2000,MATCH($A9,'Relevé hebdo'!$B$3:$B$2000,0))="",INDEX('Relevé hebdo'!$H$3:$H$2000,MATCH($A9,'Relevé hebdo'!$B$3:$B$2000,0))=0),"",LOOKUP(2,1/(('Relevé hebdo'!$B$3:$B$2000=$A9)*('Relevé hebdo'!$H$3:$H$2000<>"")),'Relevé hebdo'!$H$3:$H$2000)/INDEX('Relevé hebdo'!$H$3:$H$2000,MATCH($A9,'Relevé hebdo'!$B$3:$B$2000,0))-1),"") | F9: =IFERROR(IF(OR(INDEX('Relevé hebdo'!$J$3:$J$2000,MATCH($A9,'Relevé hebdo'!$B$3:$B$2000,0))="",INDEX('Relevé hebdo'!$J$3:$J$2000,MATCH($A9,'Relevé hebdo'!$B$3:$B$2000,0))=0),"",LOOKUP(2,1/(('Relevé hebdo'!$B$3:$B$2000=$A9)*('Relevé hebdo'!$J$3:$J$2000<>"")),'Relevé hebdo'!$J$3:$J$2000)/INDEX('Relevé hebdo'!$J$3:$J$2000,MATCH($A9,'Relevé hebdo'!$B$3:$B$2000,0))-1),"")
A10: Concurrent F | B10: =IFERROR(IF(OR(INDEX('Relevé hebdo'!$D$3:$D$2000,MATCH($A10,'Relevé hebdo'!$B$3:$B$2000,0))="",INDEX('Relevé hebdo'!$D$3:$D$2000,MATCH($A10,'Relevé hebdo'!$B$3:$B$2000,0))=0),"",LOOKUP(2,1/(('Relevé hebdo'!$B$3:$B$2000=$A10)*('Relevé hebdo'!$D$3:$D$2000<>"")),'Relevé hebdo'!$D$3:$D$2000)/INDEX('Relevé hebdo'!$D$3:$D$2000,MATCH($A10,'Relevé hebdo'!$B$3:$B$2000,0))-1),"") | C10: =IFERROR(IF(OR(INDEX('Relevé hebdo'!$E$3:$E$2000,MATCH($A10,'Relevé hebdo'!$B$3:$B$2000,0))="",INDEX('Relevé hebdo'!$E$3:$E$2000,MATCH($A10,'Relevé hebdo'!$B$3:$B$2000,0))=0),"",LOOKUP(2,1/(('Relevé hebdo'!$B$3:$B$2000=$A10)*('Relevé hebdo'!$E$3:$E$2000<>"")),'Relevé hebdo'!$E$3:$E$2000)/INDEX('Relevé hebdo'!$E$3:$E$2000,MATCH($A10,'Relevé hebdo'!$B$3:$B$2000,0))-1),"") | D10: =IFERROR(IF(OR(INDEX('Relevé hebdo'!$G$3:$G$2000,MATCH($A10,'Relevé hebdo'!$B$3:$B$2000,0))="",INDEX('Relevé hebdo'!$G$3:$G$2000,MATCH($A10,'Relevé hebdo'!$B$3:$B$2000,0))=0),"",LOOKUP(2,1/(('Relevé hebdo'!$B$3:$B$2000=$A10)*('Relevé hebdo'!$G$3:$G$2000<>"")),'Relevé hebdo'!$G$3:$G$2000)/INDEX('Relevé hebdo'!$G$3:$G$2000,MATCH($A10,'Relevé hebdo'!$B$3:$B$2000,0))-1),"") | E10: =IFERROR(IF(OR(INDEX('Relevé hebdo'!$H$3:$H$2000,MATCH($A10,'Relevé hebdo'!$B$3:$B$2000,0))="",INDEX('Relevé hebdo'!$H$3:$H$2000,MATCH($A10,'Relevé hebdo'!$B$3:$B$2000,0))=0),"",LOOKUP(2,1/(('Relevé hebdo'!$B$3:$B$2000=$A10)*('Relevé hebdo'!$H$3:$H$2000<>"")),'Relevé hebdo'!$H$3:$H$2000)/INDEX('Relevé hebdo'!$H$3:$H$2000,MATCH($A10,'Relevé hebdo'!$B$3:$B$2000,0))-1),"") | F10: =IFERROR(IF(OR(INDEX('Relevé hebdo'!$J$3:$J$2000,MATCH($A10,'Relevé hebdo'!$B$3:$B$2000,0))="",INDEX('Relevé hebdo'!$J$3:$J$2000,MATCH($A10,'Relevé hebdo'!$B$3:$B$2000,0))=0),"",LOOKUP(2,1/(('Relevé hebdo'!$B$3:$B$2000=$A10)*('Relevé hebdo'!$J$3:$J$2000<>"")),'Relevé hebdo'!$J$3:$J$2000)/INDEX('Relevé hebdo'!$J$3:$J$2000,MATCH($A10,'Relevé hebdo'!$B$3:$B$2000,0))-1),"")
A11: Concurrent G | B11: =IFERROR(IF(OR(INDEX('Relevé hebdo'!$D$3:$D$2000,MATCH($A11,'Relevé hebdo'!$B$3:$B$2000,0))="",INDEX('Relevé hebdo'!$D$3:$D$2000,MATCH($A11,'Relevé hebdo'!$B$3:$B$2000,0))=0),"",LOOKUP(2,1/(('Relevé hebdo'!$B$3:$B$2000=$A11)*('Relevé hebdo'!$D$3:$D$2000<>"")),'Relevé hebdo'!$D$3:$D$2000)/INDEX('Relevé hebdo'!$D$3:$D$2000,MATCH($A11,'Relevé hebdo'!$B$3:$B$2000,0))-1),"") | C11: =IFERROR(IF(OR(INDEX('Relevé hebdo'!$E$3:$E$2000,MATCH($A11,'Relevé hebdo'!$B$3:$B$2000,0))="",INDEX('Relevé hebdo'!$E$3:$E$2000,MATCH($A11,'Relevé hebdo'!$B$3:$B$2000,0))=0),"",LOOKUP(2,1/(('Relevé hebdo'!$B$3:$B$2000=$A11)*('Relevé hebdo'!$E$3:$E$2000<>"")),'Relevé hebdo'!$E$3:$E$2000)/INDEX('Relevé hebdo'!$E$3:$E$2000,MATCH($A11,'Relevé hebdo'!$B$3:$B$2000,0))-1),"") | D11: =IFERROR(IF(OR(INDEX('Relevé hebdo'!$G$3:$G$2000,MATCH($A11,'Relevé hebdo'!$B$3:$B$2000,0))="",INDEX('Relevé hebdo'!$G$3:$G$2000,MATCH($A11,'Relevé hebdo'!$B$3:$B$2000,0))=0),"",LOOKUP(2,1/(('Relevé hebdo'!$B$3:$B$2000=$A11)*('Relevé hebdo'!$G$3:$G$2000<>"")),'Relevé hebdo'!$G$3:$G$2000)/INDEX('Relevé hebdo'!$G$3:$G$2000,MATCH($A11,'Relevé hebdo'!$B$3:$B$2000,0))-1),"") | E11: =IFERROR(IF(OR(INDEX('Relevé hebdo'!$H$3:$H$2000,MATCH($A11,'Relevé hebdo'!$B$3:$B$2000,0))="",INDEX('Relevé hebdo'!$H$3:$H$2000,MATCH($A11,'Relevé hebdo'!$B$3:$B$2000,0))=0),"",LOOKUP(2,1/(('Relevé hebdo'!$B$3:$B$2000=$A11)*('Relevé hebdo'!$H$3:$H$2000<>"")),'Relevé hebdo'!$H$3:$H$2000)/INDEX('Relevé hebdo'!$H$3:$H$2000,MATCH($A11,'Relevé hebdo'!$B$3:$B$2000,0))-1),"") | F11: =IFERROR(IF(OR(INDEX('Relevé hebdo'!$J$3:$J$2000,MATCH($A11,'Relevé hebdo'!$B$3:$B$2000,0))="",INDEX('Relevé hebdo'!$J$3:$J$2000,MATCH($A11,'Relevé hebdo'!$B$3:$B$2000,0))=0),"",LOOKUP(2,1/(('Relevé hebdo'!$B$3:$B$2000=$A11)*('Relevé hebdo'!$J$3:$J$2000<>"")),'Relevé hebdo'!$J$3:$J$2000)/INDEX('Relevé hebdo'!$J$3:$J$2000,MATCH($A11,'Relevé hebdo'!$B$3:$B$2000,0))-1),"")

Sheet Comparatif
A1: Comparatif — complexes en colonnes · Position = rang de Le client
A3: DÉPART — semaine du 2026-06-22 (référence)
A4: Indicateur | B4: Le client | C4: Concurrent A | D4: Concurrent B | E4: Concurrent C | F4: Concurrent D | G4: Concurrent E | H4: Concurrent F | I4: Concurrent G | J4: Position Le client
A5: Note Google /5 | B5: =IFERROR(IF(INDEX('Relevé hebdo'!$C$3:$C$2000,MATCH("Le client",'Relevé hebdo'!$B$3:$B$2000,0))=0,"",INDEX('Relevé hebdo'!$C$3:$C$2000,MATCH("Le client",'Relevé hebdo'!$B$3:$B$2000,0))),"") | C5: =IFERROR(IF(INDEX('Relevé hebdo'!$C$3:$C$2000,MATCH("Concurrent A",'Relevé hebdo'!$B$3:$B$2000,0))=0,"",INDEX('Relevé hebdo'!$C$3:$C$2000,MATCH("Concurrent A",'Relevé hebdo'!$B$3:$B$2000,0))),"") | D5: =IFERROR(IF(INDEX('Relevé hebdo'!$C$3:$C$2000,MATCH("Concurrent B",'Relevé hebdo'!$B$3:$B$2000,0))=0,"",INDEX('Relevé hebdo'!$C$3:$C$2000,MATCH("Concurrent B",'Relevé hebdo'!$B$3:$B$2000,0))),"") | E5: =IFERROR(IF(INDEX('Relevé hebdo'!$C$3:$C$2000,MATCH("Concurrent C",'Relevé hebdo'!$B$3:$B$2000,0))=0,"",INDEX('Relevé hebdo'!$C$3:$C$2000,MATCH("Concurrent C",'Relevé hebdo'!$B$3:$B$2000,0))),"") | F5: =IFERROR(IF(INDEX('Relevé hebdo'!$C$3:$C$2000,MATCH("Concurrent D",'Relevé hebdo'!$B$3:$B$2000,0))=0,"",INDEX('Relevé hebdo'!$C$3:$C$2000,MATCH("Concurrent D",'Relevé hebdo'!$B$3:$B$2000,0))),"") | G5: =IFERROR(IF(INDEX('Relevé hebdo'!$C$3:$C$2000,MATCH("Concurrent E",'Relevé hebdo'!$B$3:$B$2000,0))=0,"",INDEX('Relevé hebdo'!$C$3:$C$2000,MATCH("Concurrent E",'Relevé hebdo'!$B$3:$B$2000,0))),"") | H5: =IFERROR(IF(INDEX('Relevé hebdo'!$C$3:$C$2000,MATCH("Concurrent F",'Relevé hebdo'!$B$3:$B$2000,0))=0,"",INDEX('Relevé hebdo'!$C$3:$C$2000,MATCH("Concurrent F",'Relevé hebdo'!$B$3:$B$2000,0))),"") | I5: =IFERROR(IF(INDEX('Relevé hebdo'!$C$3:$C$2000,MATCH("Concurrent G",'Relevé hebdo'!$B$3:$B$2000,0))=0,"",INDEX('Relevé hebdo'!$C$3:$C$2000,MATCH("Concurrent G",'Relevé hebdo'!$B$3:$B$2000,0))),"") | J5: =IF(ISNUMBER(B5),SUMPRODUCT(($B5:$I5>$B5)*ISNUMBER($B5:$I5))+1,"")
A6: Avis Google | B6: =IFERROR(IF(INDEX('Relevé hebdo'!$D$3:$D$2000,MATCH("Le client",'Relevé hebdo'!$B$3:$B$2000,0))=0,"",INDEX('Relevé hebdo'!$D$3:$D$2000,MATCH("Le client",'Relevé hebdo'!$B$3:$B$2000,0))),"") | C6: =IFERROR(IF(INDEX('Relevé hebdo'!$D$3:$D$2000,MATCH("Concurrent A",'Relevé hebdo'!$B$3:$B$2000,0))=0,"",INDEX('Relevé hebdo'!$D$3:$D$2000,MATCH("Concurrent A",'Relevé hebdo'!$B$3:$B$2000,0))),"") | D6: =IFERROR(IF(INDEX('Relevé hebdo'!$D$3:$D$2000,MATCH("Concurrent B",'Relevé hebdo'!$B$3:$B$2000,0))=0,"",INDEX('Relevé hebdo'!$D$3:$D$2000,MATCH("Concurrent B",'Relevé hebdo'!$B$3:$B$2000,0))),"") | E6: =IFERROR(IF(INDEX('Relevé hebdo'!$D$3:$D$2000,MATCH("Concurrent C",'Relevé hebdo'!$B$3:$B$2000,0))=0,"",INDEX('Relevé hebdo'!$D$3:$D$2000,MATCH("Concurrent C",'Relevé hebdo'!$B$3:$B$2000,0))),"") | F6: =IFERROR(IF(INDEX('Relevé hebdo'!$D$3:$D$2000,MATCH("Concurrent D",'Relevé hebdo'!$B$3:$B$2000,0))=0,"",INDEX('Relevé hebdo'!$D$3:$D$2000,MATCH("Concurrent D",'Relevé hebdo'!$B$3:$B$2000,0))),"") | G6: =IFERROR(IF(INDEX('Relevé hebdo'!$D$3:$D$2000,MATCH("Concurrent E",'Relevé hebdo'!$B$3:$B$2000,0))=0,"",INDEX('Relevé hebdo'!$D$3:$D$2000,MATCH("Concurrent E",'Relevé hebdo'!$B$3:$B$2000,0))),"") | H6: =IFERROR(IF(INDEX('Relevé hebdo'!$D$3:$D$2000,MATCH("Concurrent F",'Relevé hebdo'!$B$3:$B$2000,0))=0,"",INDEX('Relevé hebdo'!$D$3:$D$2000,MATCH("Concurrent F",'Relevé hebdo'!$B$3:$B$2000,0))),"") | I6: =IFERROR(IF(INDEX('Relevé hebdo'!$D$3:$D$2000,MATCH("Concurrent G",'Relevé hebdo'!$B$3:$B$2000,0))=0,"",INDEX('Relevé hebdo'!$D$3:$D$2000,MATCH("Concurrent G",'Relevé hebdo'!$B$3:$B$2000,0))),"") | J6: =IF(ISNUMBER(B6),SUMPRODUCT(($B6:$I6>$B6)*ISNUMBER($B6:$I6))+1,"")
A7: Abonnés Instagram | B7: =IFERROR(IF(INDEX('Relevé hebdo'!$E$3:$E$2000,MATCH("Le client",'Relevé hebdo'!$B$3:$B$2000,0))=0,"",INDEX('Relevé hebdo'!$E$3:$E$2000,MATCH("Le client",'Relevé hebdo'!$B$3:$B$2000,0))),"") | C7: =IFERROR(IF(INDEX('Relevé hebdo'!$E$3:$E$2000,MATCH("Concurrent A",'Relevé hebdo'!$B$3:$B$2000,0))=0,"",INDEX('Relevé hebdo'!$E$3:$E$2000,MATCH("Concurrent A",'Relevé hebdo'!$B$3:$B$2000,0))),"") | D7: =IFERROR(IF(INDEX('Relevé hebdo'!$E$3:$E$2000,MATCH("Concurrent B",'Relevé hebdo'!$B$3:$B$2000,0))=0,"",INDEX('Relevé hebdo'!$E$3:$E$2000,MATCH("Concurrent B",'Relevé hebdo'!$B$3:$B$2000,0))),"") | E7: =IFERROR(IF(INDEX('Relevé hebdo'!$E$3:$E$2000,MATCH("Concurrent C",'Relevé hebdo'!$B$3:$B$2000,0))=0,"",INDEX('Relevé hebdo'!$E$3:$E$2000,MATCH("Concurrent C",'Relevé hebdo'!$B$3:$B$2000,0))),"") | F7: =IFERROR(IF(INDEX('Relevé hebdo'!$E$3:$E$2000,MATCH("Concurrent D",'Relevé hebdo'!$B$3:$B$2000,0))=0,"",INDEX('Relevé hebdo'!$E$3:$E$2000,MATCH("Concurrent D",'Relevé hebdo'!$B$3:$B$2000,0))),"") | G7: =IFERROR(IF(INDEX('Relevé hebdo'!$E$3:$E$2000,MATCH("Concurrent E",'Relevé hebdo'!$B$3:$B$2000,0))=0,"",INDEX('Relevé hebdo'!$E$3:$E$2000,MATCH("Concurrent E",'Relevé hebdo'!$B$3:$B$2000,0))),"") | H7: =IFERROR(IF(INDEX('Relevé hebdo'!$E$3:$E$2000,MATCH("Concurrent F",'Relevé hebdo'!$B$3:$B$2000,0))=0,"",INDEX('Relevé hebdo'!$E$3:$E$2000,MATCH("Concurrent F",'Relevé hebdo'!$B$3:$B$2000,0))),"") | I7: =IFERROR(IF(INDEX('Relevé hebdo'!$E$3:$E$2000,MATCH("Concurrent G",'Relevé hebdo'!$B$3:$B$2000,0))=0,"",INDEX('Relevé hebdo'!$E$3:$E$2000,MATCH("Concurrent G",'Relevé hebdo'!$B$3:$B$2000,0))),"") | J7: =IF(ISNUMBER(B7),SUMPRODUCT(($B7:$I7>$B7)*ISNUMBER($B7:$I7))+1,"")
A8: Abonnés Facebook | B8: =IFERROR(IF(INDEX('Relevé hebdo'!$G$3:$G$2000,MATCH("Le client",'Relevé hebdo'!$B$3:$B$2000,0))=0,"",INDEX('Relevé hebdo'!$G$3:$G$2000,MATCH("Le client",'Relevé hebdo'!$B$3:$B$2000,0))),"") | C8: =IFERROR(IF(INDEX('Relevé hebdo'!$G$3:$G$2000,MATCH("Concurrent A",'Relevé hebdo'!$B$3:$B$2000,0))=0,"",INDEX('Relevé hebdo'!$G$3:$G$2000,MATCH("Concurrent A",'Relevé hebdo'!$B$3:$B$2000,0))),"") | D8: =IFERROR(IF(INDEX('Relevé hebdo'!$G$3:$G$2000,MATCH("Concurrent B",'Relevé hebdo'!$B$3:$B$2000,0))=0,"",INDEX('Relevé hebdo'!$G$3:$G$2000,MATCH("Concurrent B",'Relevé hebdo'!$B$3:$B$2000,0))),"") | E8: =IFERROR(IF(INDEX('Relevé hebdo'!$G$3:$G$2000,MATCH("Concurrent C",'Relevé hebdo'!$B$3:$B$2000,0))=0,"",INDEX('Relevé hebdo'!$G$3:$G$2000,MATCH("Concurrent C",'Relevé hebdo'!$B$3:$B$2000,0))),"") | F8: =IFERROR(IF(INDEX('Relevé hebdo'!$G$3:$G$2000,MATCH("Concurrent D",'Relevé hebdo'!$B$3:$B$2000,0))=0,"",INDEX('Relevé hebdo'!$G$3:$G$2000,MATCH("Concurrent D",'Relevé hebdo'!$B$3:$B$2000,0))),"") | G8: =IFERROR(IF(INDEX('Relevé hebdo'!$G$3:$G$2000,MATCH("Concurrent E",'Relevé hebdo'!$B$3:$B$2000,0))=0,"",INDEX('Relevé hebdo'!$G$3:$G$2000,MATCH("Concurrent E",'Relevé hebdo'!$B$3:$B$2000,0))),"") | H8: =IFERROR(IF(INDEX('Relevé hebdo'!$G$3:$G$2000,MATCH("Concurrent F",'Relevé hebdo'!$B$3:$B$2000,0))=0,"",INDEX('Relevé hebdo'!$G$3:$G$2000,MATCH("Concurrent F",'Relevé hebdo'!$B$3:$B$2000,0))),"") | I8: =IFERROR(IF(INDEX('Relevé hebdo'!$G$3:$G$2000,MATCH("Concurrent G",'Relevé hebdo'!$B$3:$B$2000,0))=0,"",INDEX('Relevé hebdo'!$G$3:$G$2000,MATCH("Concurrent G",'Relevé hebdo'!$B$3:$B$2000,0))),"") | J8: =IF(ISNUMBER(B8),SUMPRODUCT(($B8:$I8>$B8)*ISNUMBER($B8:$I8))+1,"")
A9: Abonnés TikTok | B9: =IFERROR(IF(INDEX('Relevé hebdo'!$H$3:$H$2000,MATCH("Le client",'Relevé hebdo'!$B$3:$B$2000,0))=0,"",INDEX('Relevé hebdo'!$H$3:$H$2000,MATCH("Le client",'Relevé hebdo'!$B$3:$B$2000,0))),"") | C9: =IFERROR(IF(INDEX('Relevé hebdo'!$H$3:$H$2000,MATCH("Concurrent A",'Relevé hebdo'!$B$3:$B$2000,0))=0,"",INDEX('Relevé hebdo'!$H$3:$H$2000,MATCH("Concurrent A",'Relevé hebdo'!$B$3:$B$2000,0))),"") | D9: =IFERROR(IF(INDEX('Relevé hebdo'!$H$3:$H$2000,MATCH("Concurrent B",'Relevé hebdo'!$B$3:$B$2000,0))=0,"",INDEX('Relevé hebdo'!$H$3:$H$2000,MATCH("Concurrent B",'Relevé hebdo'!$B$3:$B$2000,0))),"") | E9: =IFERROR(IF(INDEX('Relevé hebdo'!$H$3:$H$2000,MATCH("Concurrent C",'Relevé hebdo'!$B$3:$B$2000,0))=0,"",INDEX('Relevé hebdo'!$H$3:$H$2000,MATCH("Concurrent C",'Relevé hebdo'!$B$3:$B$2000,0))),"") | F9: =IFERROR(IF(INDEX('Relevé hebdo'!$H$3:$H$2000,MATCH("Concurrent D",'Relevé hebdo'!$B$3:$B$2000,0))=0,"",INDEX('Relevé hebdo'!$H$3:$H$2000,MATCH("Concurrent D",'Relevé hebdo'!$B$3:$B$2000,0))),"") | G9: =IFERROR(IF(INDEX('Relevé hebdo'!$H$3:$H$2000,MATCH("Concurrent E",'Relevé hebdo'!$B$3:$B$2000,0))=0,"",INDEX('Relevé hebdo'!$H$3:$H$2000,MATCH("Concurrent E",'Relevé hebdo'!$B$3:$B$2000,0))),"") | H9: =IFERROR(IF(INDEX('Relevé hebdo'!$H$3:$H$2000,MATCH("Concurrent F",'Relevé hebdo'!$B$3:$B$2000,0))=0,"",INDEX('Relevé hebdo'!$H$3:$H$2000,MATCH("Concurrent F",'Relevé hebdo'!$B$3:$B$2000,0))),"") | I9: =IFERROR(IF(INDEX('Relevé hebdo'!$H$3:$H$2000,MATCH("Concurrent G",'Relevé hebdo'!$B$3:$B$2000,0))=0,"",INDEX('Relevé hebdo'!$H$3:$H$2000,MATCH("Concurrent G",'Relevé hebdo'!$B$3:$B$2000,0))),"") | J9: =IF(ISNUMBER(B9),SUMPRODUCT(($B9:$I9>$B9)*ISNUMBER($B9:$I9))+1,"")
A10: Total abonnés | B10: =IFERROR(IF(INDEX('Relevé hebdo'!$J$3:$J$2000,MATCH("Le client",'Relevé hebdo'!$B$3:$B$2000,0))=0,"",INDEX('Relevé hebdo'!$J$3:$J$2000,MATCH("Le client",'Relevé hebdo'!$B$3:$B$2000,0))),"") | C10: =IFERROR(IF(INDEX('Relevé hebdo'!$J$3:$J$2000,MATCH("Concurrent A",'Relevé hebdo'!$B$3:$B$2000,0))=0,"",INDEX('Relevé hebdo'!$J$3:$J$2000,MATCH("Concurrent A",'Relevé hebdo'!$B$3:$B$2000,0))),"") | D10: =IFERROR(IF(INDEX('Relevé hebdo'!$J$3:$J$2000,MATCH("Concurrent B",'Relevé hebdo'!$B$3:$B$2000,0))=0,"",INDEX('Relevé hebdo'!$J$3:$J$2000,MATCH("Concurrent B",'Relevé hebdo'!$B$3:$B$2000,0))),"") | E10: =IFERROR(IF(INDEX('Relevé hebdo'!$J$3:$J$2000,MATCH("Concurrent C",'Relevé hebdo'!$B$3:$B$2000,0))=0,"",INDEX('Relevé hebdo'!$J$3:$J$2000,MATCH("Concurrent C",'Relevé hebdo'!$B$3:$B$2000,0))),"") | F10: =IFERROR(IF(INDEX('Relevé hebdo'!$J$3:$J$2000,MATCH("Concurrent D",'Relevé hebdo'!$B$3:$B$2000,0))=0,"",INDEX('Relevé hebdo'!$J$3:$J$2000,MATCH("Concurrent D",'Relevé hebdo'!$B$3:$B$2000,0))),"") | G10: =IFERROR(IF(INDEX('Relevé hebdo'!$J$3:$J$2000,MATCH("Concurrent E",'Relevé hebdo'!$B$3:$B$2000,0))=0,"",INDEX('Relevé hebdo'!$J$3:$J$2000,MATCH("Concurrent E",'Relevé hebdo'!$B$3:$B$2000,0))),"") | H10: =IFERROR(IF(INDEX('Relevé hebdo'!$J$3:$J$2000,MATCH("Concurrent F",'Relevé hebdo'!$B$3:$B$2000,0))=0,"",INDEX('Relevé hebdo'!$J$3:$J$2000,MATCH("Concurrent F",'Relevé hebdo'!$B$3:$B$2000,0))),"") | I10: =IFERROR(IF(INDEX('Relevé hebdo'!$J$3:$J$2000,MATCH("Concurrent G",'Relevé hebdo'!$B$3:$B$2000,0))=0,"",INDEX('Relevé hebdo'!$J$3:$J$2000,MATCH("Concurrent G",'Relevé hebdo'!$B$3:$B$2000,0))),"") | J10: =IF(ISNUMBER(B10),SUMPRODUCT(($B10:$I10>$B10)*ISNUMBER($B10:$I10))+1,"")
A12: ACTUEL — dernière semaine (auto)
A13: Indicateur | B13: Le client | C13: Concurrent A | D13: Concurrent B | E13: Concurrent C | F13: Concurrent D | G13: Concurrent E | H13: Concurrent F | I13: Concurrent G | J13: Position Le client
A14: Note Google /5 | B14: =IFERROR(LOOKUP(2,1/(('Relevé hebdo'!$B$3:$B$2000="Le client")*('Relevé hebdo'!$C$3:$C$2000<>"")),'Relevé hebdo'!$C$3:$C$2000),"") | C14: =IFERROR(LOOKUP(2,1/(('Relevé hebdo'!$B$3:$B$2000="Concurrent A")*('Relevé hebdo'!$C$3:$C$2000<>"")),'Relevé hebdo'!$C$3:$C$2000),"") | D14: =IFERROR(LOOKUP(2,1/(('Relevé hebdo'!$B$3:$B$2000="Concurrent B")*('Relevé hebdo'!$C$3:$C$2000<>"")),'Relevé hebdo'!$C$3:$C$2000),"") | E14: =IFERROR(LOOKUP(2,1/(('Relevé hebdo'!$B$3:$B$2000="Concurrent C")*('Relevé hebdo'!$C$3:$C$2000<>"")),'Relevé hebdo'!$C$3:$C$2000),"") | F14: =IFERROR(LOOKUP(2,1/(('Relevé hebdo'!$B$3:$B$2000="Concurrent D")*('Relevé hebdo'!$C$3:$C$2000<>"")),'Relevé hebdo'!$C$3:$C$2000),"") | G14: =IFERROR(LOOKUP(2,1/(('Relevé hebdo'!$B$3:$B$2000="Concurrent E")*('Relevé hebdo'!$C$3:$C$2000<>"")),'Relevé hebdo'!$C$3:$C$2000),"") | H14: =IFERROR(LOOKUP(2,1/(('Relevé hebdo'!$B$3:$B$2000="Concurrent F")*('Relevé hebdo'!$C$3:$C$2000<>"")),'Relevé hebdo'!$C$3:$C$2000),"") | I14: =IFERROR(LOOKUP(2,1/(('Relevé hebdo'!$B$3:$B$2000="Concurrent G")*('Relevé hebdo'!$C$3:$C$2000<>"")),'Relevé hebdo'!$C$3:$C$2000),"") | J14: =IF(ISNUMBER(B14),SUMPRODUCT(($B14:$I14>$B14)*ISNUMBER($B14:$I14))+1,"")
A15: Avis Google | B15: =IFERROR(LOOKUP(2,1/(('Relevé hebdo'!$B$3:$B$2000="Le client")*('Relevé hebdo'!$D$3:$D$2000<>"")),'Relevé hebdo'!$D$3:$D$2000),"") | C15: =IFERROR(LOOKUP(2,1/(('Relevé hebdo'!$B$3:$B$2000="Concurrent A")*('Relevé hebdo'!$D$3:$D$2000<>"")),'Relevé hebdo'!$D$3:$D$2000),"") | D15: =IFERROR(LOOKUP(2,1/(('Relevé hebdo'!$B$3:$B$2000="Concurrent B")*('Relevé hebdo'!$D$3:$D$2000<>"")),'Relevé hebdo'!$D$3:$D$2000),"") | E15: =IFERROR(LOOKUP(2,1/(('Relevé hebdo'!$B$3:$B$2000="Concurrent C")*('Relevé hebdo'!$D$3:$D$2000<>"")),'Relevé hebdo'!$D$3:$D$2000),"") | F15: =IFERROR(LOOKUP(2,1/(('Relevé hebdo'!$B$3:$B$2000="Concurrent D")*('Relevé hebdo'!$D$3:$D$2000<>"")),'Relevé hebdo'!$D$3:$D$2000),"") | G15: =IFERROR(LOOKUP(2,1/(('Relevé hebdo'!$B$3:$B$2000="Concurrent E")*('Relevé hebdo'!$D$3:$D$2000<>"")),'Relevé hebdo'!$D$3:$D$2000),"") | H15: =IFERROR(LOOKUP(2,1/(('Relevé hebdo'!$B$3:$B$2000="Concurrent F")*('Relevé hebdo'!$D$3:$D$2000<>"")),'Relevé hebdo'!$D$3:$D$2000),"") | I15: =IFERROR(LOOKUP(2,1/(('Relevé hebdo'!$B$3:$B$2000="Concurrent G")*('Relevé hebdo'!$D$3:$D$2000<>"")),'Relevé hebdo'!$D$3:$D$2000),"") | J15: =IF(ISNUMBER(B15),SUMPRODUCT(($B15:$I15>$B15)*ISNUMBER($B15:$I15))+1,"")
A16: Abonnés Instagram | B16: =IFERROR(LOOKUP(2,1/(('Relevé hebdo'!$B$3:$B$2000="Le client")*('Relevé hebdo'!$E$3:$E$2000<>"")),'Relevé hebdo'!$E$3:$E$2000),"") | C16: =IFERROR(LOOKUP(2,1/(('Relevé hebdo'!$B$3:$B$2000="Concurrent A")*('Relevé hebdo'!$E$3:$E$2000<>"")),'Relevé hebdo'!$E$3:$E$2000),"") | D16: =IFERROR(LOOKUP(2,1/(('Relevé hebdo'!$B$3:$B$2000="Concurrent B")*('Relevé hebdo'!$E$3:$E$2000<>"")),'Relevé hebdo'!$E$3:$E$2000),"") | E16: =IFERROR(LOOKUP(2,1/(('Relevé hebdo'!$B$3:$B$2000="Concurrent C")*('Relevé hebdo'!$E$3:$E$2000<>"")),'Relevé hebdo'!$E$3:$E$2000),"") | F16: =IFERROR(LOOKUP(2,1/(('Relevé hebdo'!$B$3:$B$2000="Concurrent D")*('Relevé hebdo'!$E$3:$E$2000<>"")),'Relevé hebdo'!$E$3:$E$2000),"") | G16: =IFERROR(LOOKUP(2,1/(('Relevé hebdo'!$B$3:$B$2000="Concurrent E")*('Relevé hebdo'!$E$3:$E$2000<>"")),'Relevé hebdo'!$E$3:$E$2000),"") | H16: =IFERROR(LOOKUP(2,1/(('Relevé hebdo'!$B$3:$B$2000="Concurrent F")*('Relevé hebdo'!$E$3:$E$2000<>"")),'Relevé hebdo'!$E$3:$E$2000),"") | I16: =IFERROR(LOOKUP(2,1/(('Relevé hebdo'!$B$3:$B$2000="Concurrent G")*('Relevé hebdo'!$E$3:$E$2000<>"")),'Relevé hebdo'!$E$3:$E$2000),"") | J16: =IF(ISNUMBER(B16),SUMPRODUCT(($B16:$I16>$B16)*ISNUMBER($B16:$I16))+1,"")
A17: Abonnés Facebook | B17: =IFERROR(LOOKUP(2,1/(('Relevé hebdo'!$B$3:$B$2000="Le client")*('Relevé hebdo'!$G$3:$G$2000<>"")),'Relevé hebdo'!$G$3:$G$2000),"") | C17: =IFERROR(LOOKUP(2,1/(('Relevé hebdo'!$B$3:$B$2000="Concurrent A")*('Relevé hebdo'!$G$3:$G$2000<>"")),'Relevé hebdo'!$G$3:$G$2000),"") | D17: =IFERROR(LOOKUP(2,1/(('Relevé hebdo'!$B$3:$B$2000="Concurrent B")*('Relevé hebdo'!$G$3:$G$2000<>"")),'Relevé hebdo'!$G$3:$G$2000),"") | E17: =IFERROR(LOOKUP(2,1/(('Relevé hebdo'!$B$3:$B$2000="Concurrent C")*('Relevé hebdo'!$G$3:$G$2000<>"")),'Relevé hebdo'!$G$3:$G$2000),"") | F17: =IFERROR(LOOKUP(2,1/(('Relevé hebdo'!$B$3:$B$2000="Concurrent D")*('Relevé hebdo'!$G$3:$G$2000<>"")),'Relevé hebdo'!$G$3:$G$2000),"") | G17: =IFERROR(LOOKUP(2,1/(('Relevé hebdo'!$B$3:$B$2000="Concurrent E")*('Relevé hebdo'!$G$3:$G$2000<>"")),'Relevé hebdo'!$G$3:$G$2000),"") | H17: =IFERROR(LOOKUP(2,1/(('Relevé hebdo'!$B$3:$B$2000="Concurrent F")*('Relevé hebdo'!$G$3:$G$2000<>"")),'Relevé hebdo'!$G$3:$G$2000),"") | I17: =IFERROR(LOOKUP(2,1/(('Relevé hebdo'!$B$3:$B$2000="Concurrent G")*('Relevé hebdo'!$G$3:$G$2000<>"")),'Relevé hebdo'!$G$3:$G$2000),"") | J17: =IF(ISNUMBER(B17),SUMPRODUCT(($B17:$I17>$B17)*ISNUMBER($B17:$I17))+1,"")
A18: Abonnés TikTok | B18: =IFERROR(LOOKUP(2,1/(('Relevé hebdo'!$B$3:$B$2000="Le client")*('Relevé hebdo'!$H$3:$H$2000<>"")),'Relevé hebdo'!$H$3:$H$2000),"") | C18: =IFERROR(LOOKUP(2,1/(('Relevé hebdo'!$B$3:$B$2000="Concurrent A")*('Relevé hebdo'!$H$3:$H$2000<>"")),'Relevé hebdo'!$H$3:$H$2000),"") | D18: =IFERROR(LOOKUP(2,1/(('Relevé hebdo'!$B$3:$B$2000="Concurrent B")*('Relevé hebdo'!$H$3:$H$2000<>"")),'Relevé hebdo'!$H$3:$H$2000),"") | E18: =IFERROR(LOOKUP(2,1/(('Relevé hebdo'!$B$3:$B$2000="Concurrent C")*('Relevé hebdo'!$H$3:$H$2000<>"")),'Relevé hebdo'!$H$3:$H$2000),"") | F18: =IFERROR(LOOKUP(2,1/(('Relevé hebdo'!$B$3:$B$2000="Concurrent D")*('Relevé hebdo'!$H$3:$H$2000<>"")),'Relevé hebdo'!$H$3:$H$2000),"") | G18: =IFERROR(LOOKUP(2,1/(('Relevé hebdo'!$B$3:$B$2000="Concurrent E")*('Relevé hebdo'!$H$3:$H$2000<>"")),'Relevé hebdo'!$H$3:$H$2000),"") | H18: =IFERROR(LOOKUP(2,1/(('Relevé hebdo'!$B$3:$B$2000="Concurrent F")*('Relevé hebdo'!$H$3:$H$2000<>"")),'Relevé hebdo'!$H$3:$H$2000),"") | I18: =IFERROR(LOOKUP(2,1/(('Relevé hebdo'!$B$3:$B$2000="Concurrent G")*('Relevé hebdo'!$H$3:$H$2000<>"")),'Relevé hebdo'!$H$3:$H$2000),"") | J18: =IF(ISNUMBER(B18),SUMPRODUCT(($B18:$I18>$B18)*ISNUMBER($B18:$I18))+1,"")
A19: Total abonnés | B19: =IFERROR(LOOKUP(2,1/(('Relevé hebdo'!$B$3:$B$2000="Le client")*('Relevé hebdo'!$J$3:$J$2000<>"")),'Relevé hebdo'!$J$3:$J$2000),"") | C19: =IFERROR(LOOKUP(2,1/(('Relevé hebdo'!$B$3:$B$2000="Concurrent A")*('Relevé hebdo'!$J$3:$J$2000<>"")),'Relevé hebdo'!$J$3:$J$2000),"") | D19: =IFERROR(LOOKUP(2,1/(('Relevé hebdo'!$B$3:$B$2000="Concurrent B")*('Relevé hebdo'!$J$3:$J$2000<>"")),'Relevé hebdo'!$J$3:$J$2000),"") | E19: =IFERROR(LOOKUP(2,1/(('Relevé hebdo'!$B$3:$B$2000="Concurrent C")*('Relevé hebdo'!$J$3:$J$2000<>"")),'Relevé hebdo'!$J$3:$J$2000),"") | F19: =IFERROR(LOOKUP(2,1/(('Relevé hebdo'!$B$3:$B$2000="Concurrent D")*('Relevé hebdo'!$J$3:$J$2000<>"")),'Relevé hebdo'!$J$3:$J$2000),"") | G19: =IFERROR(LOOKUP(2,1/(('Relevé hebdo'!$B$3:$B$2000="Concurrent E")*('Relevé hebdo'!$J$3:$J$2000<>"")),'Relevé hebdo'!$J$3:$J$2000),"") | H19: =IFERROR(LOOKUP(2,1/(('Relevé hebdo'!$B$3:$B$2000="Concurrent F")*('Relevé hebdo'!$J$3:$J$2000<>"")),'Relevé hebdo'!$J$3:$J$2000),"") | I19: =IFERROR(LOOKUP(2,1/(('Relevé hebdo'!$B$3:$B$2000="Concurrent G")*('Relevé hebdo'!$J$3:$J$2000<>"")),'Relevé hebdo'!$J$3:$J$2000),"") | J19: =IF(ISNUMBER(B19),SUMPRODUCT(($B19:$I19>$B19)*ISNUMBER($B19:$I19))+1,"")
A21: ÉVOLUTION — Départ → Actuel
A22: Indicateur | B22: Le client | C22: Concurrent A | D22: Concurrent B | E22: Concurrent C | F22: Concurrent D | G22: Concurrent E | H22: Concurrent F | I22: Concurrent G | J22: Position Le client
A23: Note Google /5 | B23: =IF(AND(ISNUMBER(B14),ISNUMBER(B5)),B14-B5,"") | C23: =IF(AND(ISNUMBER(C14),ISNUMBER(C5)),C14-C5,"") | D23: =IF(AND(ISNUMBER(D14),ISNUMBER(D5)),D14-D5,"") | E23: =IF(AND(ISNUMBER(E14),ISNUMBER(E5)),E14-E5,"") | F23: =IF(AND(ISNUMBER(F14),ISNUMBER(F5)),F14-F5,"") | G23: =IF(AND(ISNUMBER(G14),ISNUMBER(G5)),G14-G5,"") | H23: =IF(AND(ISNUMBER(H14),ISNUMBER(H5)),H14-H5,"") | I23: =IF(AND(ISNUMBER(I14),ISNUMBER(I5)),I14-I5,"") | J23: =IF(ISNUMBER(B23),SUMPRODUCT(($B23:$I23>$B23)*ISNUMBER($B23:$I23))+1,"")
A24: Avis Google | B24: =IF(AND(ISNUMBER(B15),ISNUMBER(B6)),B15-B6,"") | C24: =IF(AND(ISNUMBER(C15),ISNUMBER(C6)),C15-C6,"") | D24: =IF(AND(ISNUMBER(D15),ISNUMBER(D6)),D15-D6,"") | E24: =IF(AND(ISNUMBER(E15),ISNUMBER(E6)),E15-E6,"") | F24: =IF(AND(ISNUMBER(F15),ISNUMBER(F6)),F15-F6,"") | G24: =IF(AND(ISNUMBER(G15),ISNUMBER(G6)),G15-G6,"") | H24: =IF(AND(ISNUMBER(H15),ISNUMBER(H6)),H15-H6,"") | I24: =IF(AND(ISNUMBER(I15),ISNUMBER(I6)),I15-I6,"") | J24: =IF(ISNUMBER(B24),SUMPRODUCT(($B24:$I24>$B24)*ISNUMBER($B24:$I24))+1,"")
A25: Abonnés Instagram | B25: =IF(AND(ISNUMBER(B16),ISNUMBER(B7)),B16-B7,"") | C25: =IF(AND(ISNUMBER(C16),ISNUMBER(C7)),C16-C7,"") | D25: =IF(AND(ISNUMBER(D16),ISNUMBER(D7)),D16-D7,"") | E25: =IF(AND(ISNUMBER(E16),ISNUMBER(E7)),E16-E7,"") | F25: =IF(AND(ISNUMBER(F16),ISNUMBER(F7)),F16-F7,"") | G25: =IF(AND(ISNUMBER(G16),ISNUMBER(G7)),G16-G7,"") | H25: =IF(AND(ISNUMBER(H16),ISNUMBER(H7)),H16-H7,"") | I25: =IF(AND(ISNUMBER(I16),ISNUMBER(I7)),I16-I7,"") | J25: =IF(ISNUMBER(B25),SUMPRODUCT(($B25:$I25>$B25)*ISNUMBER($B25:$I25))+1,"")
A26: Abonnés Facebook | B26: =IF(AND(ISNUMBER(B17),ISNUMBER(B8)),B17-B8,"") | C26: =IF(AND(ISNUMBER(C17),ISNUMBER(C8)),C17-C8,"") | D26: =IF(AND(ISNUMBER(D17),ISNUMBER(D8)),D17-D8,"") | E26: =IF(AND(ISNUMBER(E17),ISNUMBER(E8)),E17-E8,"") | F26: =IF(AND(ISNUMBER(F17),ISNUMBER(F8)),F17-F8,"") | G26: =IF(AND(ISNUMBER(G17),ISNUMBER(G8)),G17-G8,"") | H26: =IF(AND(ISNUMBER(H17),ISNUMBER(H8)),H17-H8,"") | I26: =IF(AND(ISNUMBER(I17),ISNUMBER(I8)),I17-I8,"") | J26: =IF(ISNUMBER(B26),SUMPRODUCT(($B26:$I26>$B26)*ISNUMBER($B26:$I26))+1,"")
A27: Abonnés TikTok | B27: =IF(AND(ISNUMBER(B18),ISNUMBER(B9)),B18-B9,"") | C27: =IF(AND(ISNUMBER(C18),ISNUMBER(C9)),C18-C9,"") | D27: =IF(AND(ISNUMBER(D18),ISNUMBER(D9)),D18-D9,"") | E27: =IF(AND(ISNUMBER(E18),ISNUMBER(E9)),E18-E9,"") | F27: =IF(AND(ISNUMBER(F18),ISNUMBER(F9)),F18-F9,"") | G27: =IF(AND(ISNUMBER(G18),ISNUMBER(G9)),G18-G9,"") | H27: =IF(AND(ISNUMBER(H18),ISNUMBER(H9)),H18-H9,"") | I27: =IF(AND(ISNUMBER(I18),ISNUMBER(I9)),I18-I9,"") | J27: =IF(ISNUMBER(B27),SUMPRODUCT(($B27:$I27>$B27)*ISNUMBER($B27:$I27))+1,"")
A28: Total abonnés | B28: =IF(AND(ISNUMBER(B19),ISNUMBER(B10)),B19-B10,"") | C28: =IF(AND(ISNUMBER(C19),ISNUMBER(C10)),C19-C10,"") | D28: =IF(AND(ISNUMBER(D19),ISNUMBER(D10)),D19-D10,"") | E28: =IF(AND(ISNUMBER(E19),ISNUMBER(E10)),E19-E10,"") | F28: =IF(AND(ISNUMBER(F19),ISNUMBER(F10)),F19-F10,"") | G28: =IF(AND(ISNUMBER(G19),ISNUMBER(G10)),G19-G10,"") | H28: =IF(AND(ISNUMBER(H19),ISNUMBER(H10)),H19-H10,"") | I28: =IF(AND(ISNUMBER(I19),ISNUMBER(I10)),I19-I10,"") | J28: =IF(ISNUMBER(B28),SUMPRODUCT(($B28:$I28>$B28)*ISNUMBER($B28:$I28))+1,"")
A31: Position = rang de Le client sur la ligne (1 = meilleur), parmi les complexes ayant une donnée comparable. Comptes nationaux exclus.
