Workbook

Sheet Rentabilite
A1: KAMPUS 137 - Etude de rentabilite : GRANITES (Fournisseur / Fournisseur)
A2: Source : Offre SELI Fournisseur - contrat 36 mois - Liste de prix HT 2026 Blue 6 - etabli le 26/06/2026
A4: PARAMETRE | B4: VALEUR | C4: UNITE | D4: NOTE
A5: 1) CONTRAT & MACHINE
A6: Loyer machine 2 bacs | B6: 50 | C6: EUR HT/mois | D6: au lieu de 60 EUR (remise SELI)
A7: Frais d'installation (one-shot) | B7: 90 | C7: EUR HT | D7: au lieu de 180 EUR (remise SELI)
A8: Duree du contrat | B8: 36 | C8: mois
A9: Mois offert(s) | B9: 1 | C9: mois | D9: 1er mois apres installation offert
A11: 2) SIROP & PORTION
A12: Prix BIB sirop 10 L | C12: EUR HT | D12: tous parfums (framboise, fraise, cola...)
A13: Ratio dilution (1 sirop : X eau) | B13: 6.8 | D13: indique 1/6,8 sur la liste de prix
A14: Volume de granite par BIB | B14: =10*(1+B13) | C14: L | D14: 10 L sirop x (1 + ratio)
A15: Volume d'une portion | B15: 300 | C15: ml | D15: editable (gobelet 341 ml)
A16: Portions par BIB | B16: =B14*1000/B15 | C16: portions
A17: Cout sirop par granite | B17: =B12/B16 | C17: EUR HT | D17: prix BIB / portions par BIB
A19: 3) CONSOMMABLES (par granite)
A20: Gobelet papier 341 ml | B20: =82.98/1140 | C20: EUR HT | D20: 82,98 EUR / 1140 pcs
A21: Paille | B21: =87.17/2500 | C21: EUR HT | D21: 87,17 EUR / 2500 pcs
A22: Couvercle 90 mm | B22: =94.84/1000 | C22: EUR HT | D22: 94,84 EUR / 1000 pcs
A23: Inclure couvercle ? (1=oui/0=non) | B23: 1 | D23: mettre 0 si service sans couvercle
A24: Cout consommables / granite | B24: =B20+B21+B22*B23 | C24: EUR HT
A26: 4) COUT, PRIX & MARGE
A27: Cout variable total / granite | B27: =B17+B24 | C27: EUR HT | D27: sirop + consommables
A28: TVA | B28: 0.1 | D28: boisson a consommer sur place = 10%
A29: PRIX SEUIL plancher / granite (TTC) | B29: =B27*(1+B28) | C29: EUR TTC | D29: en-dessous = perte sur chaque granite
A30: Prix de vente public (retenu) | B30: 3.5 | C30: EUR TTC | D30: EDITABLE - prix retenu pour les scenarios
A31: Prix de vente HT | B31: =B30/(1+B28) | C31: EUR HT
A32: Marge brute / granite | B32: =B31-B27 | C32: EUR HT | D32: marge sur cout variable
A33: Taux de marge | B33: =B32/B31 | C33: %
A35: 5) SEUIL DE RENTABILITE & INVESTISSEMENT
A36: Charges fixes completes / mois | B36: =B6+B7/B8 | C36: EUR HT/mois | D36: loyer + installation amortie sur 36 mois
A37: QUANTITE MIN / mois (point mort) | B37: =B36/B32 | C37: granites/mois | D37: couvre loyer + installation
A38: Jours d'ouverture / an | B38: 225 | C38: jours
A39: Jours d'ouverture / mois | B39: =B38/12 | C39: jours
A40: QUANTITE MIN / jour d'ouverture | B40: =B37/B39 | C40: granites/jour
A41: Cout total du contrat (36 mois) | B41: =B6*(B8-B9)+B7 | C41: EUR HT | D41: loyer x (36 - 1 offert) + installation
A42: Volume pour amortir TOUT le contrat | B42: =B41/B32 | C42: granites | D42: sur 36 mois
A44: 6) SCENARIOS DE VENTE (au prix retenu en B30)
A45: Granites / jour | B45: Granites / mois | C45: CA TTC / mois | D45: Marge brute / mois (HT) | E45: Charges fixes / mois | F45: Resultat net / mois (HT) | G45: Resultat net / an (HT)
A46: 5 | B46: =A46*$B$39 | C46: =B46*$B$30 | D46: =B46*$B$32 | E46: =$B$36 | F46: =D46-E46 | G46: =F46*12
...

Sheet Comparatif 3-3,5
A1: COMPARATIF PRIX 3,00 EUR vs 3,50 EUR + prix seuil & quantite mini
A3: INDICATEUR | B3: Hypothese 3,00 EUR | C3: Hypothese 3,50 EUR
A4: Prix de vente (TTC) | B4: 3 | C4: 3.5
A5: Prix de vente (HT) | B5: =B4/(1+Rentabilite!$B$28) | C5: =C4/(1+Rentabilite!$B$28)
A6: Cout variable / granite (HT) | B6: =Rentabilite!$B$27 | C6: =Rentabilite!$B$27
A7: Marge brute / granite (HT) | B7: =B5-B6 | C7: =C5-C6
A8: Taux de marge | B8: =B7/B5 | C8: =C7/C5
A9: Charges fixes completes / mois | B9: =Rentabilite!$B$36 | C9: =Rentabilite!$B$36
A10: PRIX SEUIL plancher (TTC) | B10: =B6*(1+Rentabilite!$B$28) | C10: =C6*(1+Rentabilite!$B$28)
A11: QUANTITE MIN / mois (point mort) | B11: =B9/B7 | C11: =C9/C7
A12: QUANTITE MIN / jour d'ouverture | B12: =B11/Rentabilite!$B$39 | C12: =C11/Rentabilite!$B$39
A13: Rappel : seuil loyer seul / mois | B13: =Rentabilite!$B$6/B7 | C13: =Rentabilite!$B$6/C7
A16: Granites / mois | B16: Resultat net @3,00 EUR | C16: Resultat net @3,50 EUR
A17: 0 | B17: =A17*$B$7-$B$9 | C17: =A17*$C$7-$C$9
A18: 10 | B18: =A18*$B$7-$B$9 | C18: =A18*$C$7-$C$9
A19: 20 | B19: =A19*$B$7-$B$9 | C19: =A19*$C$7-$C$9
A20: 30 | B20: =A20*$B$7-$B$9 | C20: =A20*$C$7-$C$9
A21: 40 | B21: =A21*$B$7-$B$9 | C21: =A21*$C$7-$C$9
A22: 50 | B22: =A22*$B$7-$B$9 | C22: =A22*$C$7-$C$9
A23: 60 | B23: =A23*$B$7-$B$9 | C23: =A23*$C$7-$C$9
A24: 80 | B24: =A24*$B$7-$B$9 | C24: =A24*$C$7-$C$9
A25: 100 | B25: =A25*$B$7-$B$9 | C25: =A25*$C$7-$C$9
A26: 150 | B26: =A26*$B$7-$B$9 | C26: =A26*$C$7-$C$9
A27: 200 | B27: =A27*$B$7-$B$9 | C27: =A27*$C$7-$C$9
A29: Granites / jour | B29: Net / an @3,00 EUR | C29: Net / an @3,50 EUR
A30: 5 | B30: =(A30*Rentabilite!$B$39*$B$7-$B$9)*12 | C30: =(A30*Rentabilite!$B$39*$C$7-$C$9)*12
A31: 10 | B31: =(A31*Rentabilite!$B$39*$B$7-$B$9)*12 | C31: =(A31*Rentabilite!$B$39*$C$7-$C$9)*12
A32: 15 | B32: =(A32*Rentabilite!$B$39*$B$7-$B$9)*12 | C32: =(A32*Rentabilite!$B$39*$C$7-$C$9)*12
A33: 20 | B33: =(A33*Rentabilite!$B$39*$B$7-$B$9)*12 | C33: =(A33*Rentabilite!$B$39*$C$7-$C$9)*12
A34: 30 | B34: =(A34*Rentabilite!$B$39*$B$7-$B$9)*12 | C34: =(A34*Rentabilite!$B$39*$C$7-$C$9)*12
A35: 50 | B35: =(A35*Rentabilite!$B$39*$B$7-$B$9)*12 | C35: =(A35*Rentabilite!$B$39*$C$7-$C$9)*12
